990
996
1
2
3
4
5
6
7
8
9
10
999
terminate called after throwing an instance of 'std::runtime_error'
  what():  Break occurred outside a while loop.
